Workbook

Sheet Basis
B2: D2 — Critical Velocity & Preliminary Fan Sizing
B3: Memorial Tunnel TVS | Doc. STN-MT-CVC-002 Rev A | Synoptic CFD
B5: Purpose | C5: Analytical (hand-calc) determination of critical velocity and jet-fan requirement for each design fire, prior to and independent of SES. Establishes the target the SES model must confirm.
B6: Method — Critical velocity | C6: Froude-number formulation (NFPA 502 / Kennedy). Vc and fire-site temperature Tf are coupled and solved iteratively.
B7: Method — Fan sizing | C7: Momentum/thrust balance: required tunnel pressure rise vs. installed jet-fan thrust; fan count = ceil(required thrust / thrust per fan / installation efficiency).
B8: Grade correction | C8: Grade factor Kg applied for the 3.2% uphill gradient (buoyancy assists smoke up-grade, raising Vc).
B9: Colour convention | C9: Blue = input you may change. Black = formula. Green = cross-sheet link. Yellow = key assumption.
B10: Governing value | C10: Where the analytical Vc and the MTFVTP measured band (~2.5–3.0 m/s) differ, the higher is carried forward as the design target.
B11: Sheets | C11: Basis (this) · Inputs · CriticalVelocity · FanSizing · Summary

Sheet Methodology
B2: Methodology & Worked Calculations
B3: How every number in this workbook is derived — for client review. STN-MT-CVC-002 Rev A
B5: This sheet documents the equations, their sources, and a fully worked example so that the results on the CriticalVelocity, FanSizing and Summary sheets can be reproduced and audited by hand. Every equation below is implemented live in the calculation sheets; the cell formulas reference the Inputs sheet so that changing any input updates all results.
B8: 1. Critical Velocity — Froude-Number Method (NFPA 502 / Kennedy)
B10: The critical velocity Vc is the minimum longitudinal air velocity that prevents smoke from travelling upstream (back-layering) against the ventilation flow. It is found from a dimensionless balance between the buoyancy of the hot smoke and the momentum of the ventilation air (a critical Froude number of unity). Because the buoyancy depends on the smoke temperature, and the smoke temperature at the fire site depends in turn on how fast the air is moving, the two equations are coupled and solved iteratively.
B14: Governing equations:
B15: Vc = Kg · Kf · [ g · H · Qc / (ρ₀ · cp · A · Tf) ] ^ (1/3)
B17: Tf = Qc / (ρ₀ · cp · A · Vc) + T₀
B19: Kg = 1 + 0.0374 · |grade%| ^ 0.8 (grade correction factor)
B22: Symbols:
B23: Vc | C23: Critical velocity [m/s] — the result we solve for
B24: Qc | C24: Convective heat release rate [W] = (convective fraction) × total HRR. Only the convective part heats the moving air and drives buoyancy.
B25: Tf | C25: Absolute gas temperature at the fire site [K]
B26: Kf | C26: Froude constant = 0.606 (Kennedy calibration of the critical-Froude criterion)
B27: Kg | C27: Grade factor — uphill grade lets hot smoke rise more easily, so Vc must increase
B28: g | C28: 9.81 m/s² · H = hydraulic height (area ÷ width) [m] · A = tunnel area [m²]
B29: ρ₀ | C29: Ambient air density [kg/m³] · cp = specific heat of air [J/kg·K] · T₀ = ambient temp [K]
B31: Solution procedure (successive substitution):
B32: 1. Seed the velocity: Vc₀ = 2.5 m/s.
B33: 2. Compute the fire-site temperature Tf from the current Vc (equation 2).
B34: 3. Recompute Vc from that Tf (equation 1).
B35: 4. Repeat. The value converges within ~4 iterations; the workbook runs 5 for margin.
B36: 5. The design critical velocity is the greater of the analytical Vc and the 3.0 m/s conservative guard from the MTFVTP measured band (~2.5–3.0 m/s).
B38: 2. Worked Example — 100 MW Design Fire (Test 615B)
B40: Using the Inputs values: g = 9.81, H = 6.86 m, A = 60.4 m², ρ₀ = 1.20 kg/m³, cp = 1005 J/kg·K, T₀ = 288.15 K, Kf = 0.606, grade = 3.2%, convective fraction = 0.70, and total HRR = 102,659 kW.
B43: Convective HRR | C43: Qc = 0.70 × 102,659 kW = 71,861 kW = 71.86 × 10⁶ W
B44: Grade factor | C44: Kg = 1 + 0.0374 × 3.2^0.8 = 1 + 0.0374 × 2.52 = 1.094
B45: Iteration 1 — Tf | C45: Tf = 71.86e6 / (1.20 × 1005 × 60.4 × 2.5) + 288.15 = 394.7 + 288.15 = 682.9 K
B46: Iteration 1 — Vc | C46: Vc = 1.094 × 0.606 × [9.81 × 6.86 × 71.86e6 / (1.20 × 1005 × 60.4 × 682.9)]^(1/3) = 3.28 m/s
B47: Iteration 2 — Tf | C47: Tf = 71.86e6 / (1.20 × 1005 × 60.4 × 3.28) + 288.15 = 300.8 + 288.15 = 589.0 K
B48: Iteration 2 — Vc | C48: Vc = 1.094 × 0.606 × [ … / (… × 589.0)]^(1/3) = 3.17 m/s
B49: Converged | C49: After 5 iterations Vc → 3.19 m/s ; Tf → 597.5 K = 324 °C
B50: Design Vc | C50: max(3.19, 3.0) = 3.19 m/s ← governing critical velocity for the 100 MW fire
B53: 3. Preliminary Fan Sizing — Momentum / Thrust Balance
B55: To establish the design critical velocity Vc along the tunnel, the jet fans must supply enough thrust to overcome the tunnel's aerodynamic resistance at that velocity. The resistance has two parts: wall friction along the length, and the sum of minor (entry, exit, obstruction) losses.
B58: Governing equations:
B59: ΔP = ( f · L / Dh + ΣK ) · ½ · ρ₀ · Vc² (pressure rise needed) [Pa]
B61: Dh = 4 · A / P (hydraulic diameter) [m]
B63: F_required = ΔP · A (total thrust) [N]
B65: F_fan = ρ₀ · Qfan · (Vjet − Vc) · k_inst · η (thrust per jet fan) [N]
...

Sheet Inputs
B2: Inputs & Constants
B3: Blue cells are editable. Yellow = key assumption.
B4: Physical constants
B5: Symbol | C5: Description | D5: Value | E5: Unit | F5: Type
B6: g | C6: Gravitational acceleration | D6: 9.81 | E6: m/s² | F6: input
B7: rho0 | C7: Ambient air density | D7: 1.2 | E7: kg/m³ | F7: input
B8: cp | C8: Specific heat of air | D8: 1005 | E8: J/kg·K | F8: input
B9: T0 | C9: Ambient air temperature (design) | D9: 288.15 | E9: K | F9: input
B10: K_fr | C10: Froude constant (Kennedy) | D10: 0.606 | E10: - | F10: input
B12: Tunnel geometry
B13: Symbol | C13: Description | D13: Value | E13: Unit | F13: Source
B14: A | C14: Cross-sectional area | D14: 60.4 | E14: m² | F14: MTFVTP reports
B15: H | C15: Hydraulic height (A/W) | D15: 6.86 | E15: m | F15: A / roadway width 8.8 m
B16: Per | C16: Wetted perimeter | D16: 27.5 | E16: m | F16: Arched section, MTFVTP
B17: L | C17: Tunnel length | D17: 853.75 | E17: m | F17: Sum of 45 SES segments
B18: grade | C18: Gradient (uphill S→N) | D18: 3.2 | E18: % | F18: MTFVTP reports
B19: f | C19: Darcy friction factor | D19: 0.022 | E19: - | F19: 4 × Fanning 0.0055 (DBR)
B20: Kmin | C20: Total minor K-loss | D20: 13.1 | E20: - | F20: DBR §4.2
B22: Jet fan data
B23: Symbol | C23: Description | D23: Value | E23: Unit | F23: Source
B24: Qfan | C24: Volume flow per jet fan | D24: 42.95 | E24: m³/s | F24: DBR §4.1
B25: Vjet | C25: Jet discharge velocity | D25: 34.2 | E25: m/s | F25: DBR §4.1
B26: eta | C26: Pressure/installation efficiency | D26: 0.8 | E26: - | F26: Mid of 75–83% band
B27: k_inst | C27: Jet-fan installation factor | D27: 0.9 | E27: - | F27: Wall-proximity thrust derate

Sheet CriticalVelocity
B2: Critical Velocity — Froude Method (iterative)
B3: Vc and Tf solved by successive substitution (5 iterations). Grade-corrected.
B4: Convective heat fraction of HRR | C4: 0.7 | D4: portion of fire power heating the moving air (0.6–0.75 typical)
I6: Equations (see Methodology sheet for full derivation & worked example):
B7: Parameter / Fire | C7: 10 MW (Test 606A) | D7: 20 MW (Test 607) | E7: 50 MW (Test 611) | F7: 100 MW (Test 615B)
B8: Total HRR Q [kW] | C8: 10445 | D8: 14138 | E8: 49202 | F8: 102659 | I8: Q = measured quasi-steady HRR per design fire
B9: Convective HRR Qc [kW] | C9: =C8*$C$4 -> 7311.5 | D9: =D8*$C$4 -> 9896.6 | E9: =E8*$C$4 -> 34441.4 | F9: =F8*$C$4 -> 71861.3 | I9: Qc = Q × convective fraction
B10: Grade factor Kg [-] | C10: =1+0.0374*ABS(Inputs!$D$18)^0.8 -> 1.09484 | D10: =1+0.0374*ABS(Inputs!$D$18)^0.8 -> 1.09484 | E10: =1+0.0374*ABS(Inputs!$D$18)^0.8 -> 1.09484 | F10: =1+0.0374*ABS(Inputs!$D$18)^0.8 -> 1.09484 | I10: Kg = 1 + 0.0374·|grade%|^0.8
B12: Iterative solution (Vc₀ seed = 2.5 m/s)
B13: Iteration | C13: 10 MW | D13: 20 MW | E13: 50 MW | F13: 100 MW
B14: Vc seed (m/s) | C14: 2.5 | D14: 2.5 | E14: 2.5 | F14: 2.5
B15: Tf1 (K) | C15: =C9*1000/(Inputs!$D$7*Inputs!$D$8*Inputs!$D$14*C14)+Inputs!$D$9 -> 328.29969 | D15: =D9*1000/(Inputs!$D$7*Inputs!$D$8*Inputs!$D$14*D14)+Inputs!$D$9 -> 342.49527 | E15: =E9*1000/(Inputs!$D$7*Inputs!$D$8*Inputs!$D$14*E14)+Inputs!$D$9 -> 477.27831 | F15: =F9*1000/(Inputs!$D$7*Inputs!$D$8*Inputs!$D$14*F14)+Inputs!$D$9 -> 682.76248 | I15: Tf = Qc·1000/(ρ₀·cp·A·Vc) + T₀ [K]
B16: Vc1 (m/s) | C16: =C10*Inputs!$D$10*(Inputs!$D$6*Inputs!$D$15*C9*1000/(Inputs!$D$7*Inputs!$D$8*Inputs!$D$14*C15))^(1/3) -> 1.8180462 | D16: =D10*Inputs!$D$10*(Inputs!$D$6*Inputs!$D$15*D9*1000/(Inputs!$D$7*Inputs!$D$8*Inputs!$D$14*D15))^(1/3) -> 1.9829118 | E16: =E10*Inputs!$D$10*(Inputs!$D$6*Inputs!$D$15*E9*1000/(Inputs!$D$7*Inputs!$D$8*Inputs!$D$14*E15))^(1/3) -> 2.6902705 | F16: =F10*Inputs!$D$10*(Inputs!$D$6*Inputs!$D$15*F9*1000/(Inputs!$D$7*Inputs!$D$8*Inputs!$D$14*F15))^(1/3) -> 3.0509474 | I16: Vc = Kg·Kf·[g·H·Qc·1000/(ρ₀·cp·A·Tf)]^(1/3)
B17: Tf2 (K) | C17: =C9*1000/(Inputs!$D$7*Inputs!$D$8*Inputs!$D$14*C16)+Inputs!$D$9 -> 343.35995 | D17: =D9*1000/(Inputs!$D$7*Inputs!$D$8*Inputs!$D$14*D16)+Inputs!$D$9 -> 356.66701 | E17: =E9*1000/(Inputs!$D$7*Inputs!$D$8*Inputs!$D$14*E16)+Inputs!$D$9 -> 463.90213 | F17: =F9*1000/(Inputs!$D$7*Inputs!$D$8*Inputs!$D$14*F16)+Inputs!$D$9 -> 611.50241
B18: Vc2 (m/s) | C18: =C10*Inputs!$D$10*(Inputs!$D$6*Inputs!$D$15*C9*1000/(Inputs!$D$7*Inputs!$D$8*Inputs!$D$14*C17))^(1/3) -> 1.7910671 | D18: =D10*Inputs!$D$10*(Inputs!$D$6*Inputs!$D$15*D9*1000/(Inputs!$D$7*Inputs!$D$8*Inputs!$D$14*D17))^(1/3) -> 1.9562932 | E18: =E10*Inputs!$D$10*(Inputs!$D$6*Inputs!$D$15*E9*1000/(Inputs!$D$7*Inputs!$D$8*Inputs!$D$14*E17))^(1/3) -> 2.715883 | F18: =F10*Inputs!$D$10*(Inputs!$D$6*Inputs!$D$15*F9*1000/(Inputs!$D$7*Inputs!$D$8*Inputs!$D$14*F17))^(1/3) -> 3.1651323
B19: Tf3 (K) | C19: =C9*1000/(Inputs!$D$7*Inputs!$D$8*Inputs!$D$14*C18)+Inputs!$D$9 -> 344.19158 | D19: =D9*1000/(Inputs!$D$7*Inputs!$D$8*Inputs!$D$14*D18)+Inputs!$D$9 -> 357.59929 | E19: =E9*1000/(Inputs!$D$7*Inputs!$D$8*Inputs!$D$14*E18)+Inputs!$D$9 -> 462.24468 | F19: =F9*1000/(Inputs!$D$7*Inputs!$D$8*Inputs!$D$14*F18)+Inputs!$D$9 -> 599.83719
B20: Vc3 (m/s) | C20: =C10*Inputs!$D$10*(Inputs!$D$6*Inputs!$D$15*C9*1000/(Inputs!$D$7*Inputs!$D$8*Inputs!$D$14*C19))^(1/3) -> 1.7896234 | D20: =D10*Inputs!$D$10*(Inputs!$D$6*Inputs!$D$15*D9*1000/(Inputs!$D$7*Inputs!$D$8*Inputs!$D$14*D19))^(1/3) -> 1.9545916 | E20: =E10*Inputs!$D$10*(Inputs!$D$6*Inputs!$D$15*E9*1000/(Inputs!$D$7*Inputs!$D$8*Inputs!$D$14*E19))^(1/3) -> 2.7191252 | F20: =F10*Inputs!$D$10*(Inputs!$D$6*Inputs!$D$15*F9*1000/(Inputs!$D$7*Inputs!$D$8*Inputs!$D$14*F19))^(1/3) -> 3.1855185
B21: Tf4 (K) | C21: =C9*1000/(Inputs!$D$7*Inputs!$D$8*Inputs!$D$14*C20)+Inputs!$D$9 -> 344.23679 | D21: =D9*1000/(Inputs!$D$7*Inputs!$D$8*Inputs!$D$14*D20)+Inputs!$D$9 -> 357.65975 | E21: =E9*1000/(Inputs!$D$7*Inputs!$D$8*Inputs!$D$14*E20)+Inputs!$D$9 -> 462.03709 | F21: =F9*1000/(Inputs!$D$7*Inputs!$D$8*Inputs!$D$14*F20)+Inputs!$D$9 -> 597.8425
B22: Vc4 (m/s) | C22: =C10*Inputs!$D$10*(Inputs!$D$6*Inputs!$D$15*C9*1000/(Inputs!$D$7*Inputs!$D$8*Inputs!$D$14*C21))^(1/3) -> 1.7895451 | D22: =D10*Inputs!$D$10*(Inputs!$D$6*Inputs!$D$15*D9*1000/(Inputs!$D$7*Inputs!$D$8*Inputs!$D$14*D21))^(1/3) -> 1.9544815 | E22: =E10*Inputs!$D$10*(Inputs!$D$6*Inputs!$D$15*E9*1000/(Inputs!$D$7*Inputs!$D$8*Inputs!$D$14*E21))^(1/3) -> 2.7195323 | F22: =F10*Inputs!$D$10*(Inputs!$D$6*Inputs!$D$15*F9*1000/(Inputs!$D$7*Inputs!$D$8*Inputs!$D$14*F21))^(1/3) -> 3.1890574
B23: Tf5 (K) | C23: =C9*1000/(Inputs!$D$7*Inputs!$D$8*Inputs!$D$14*C22)+Inputs!$D$9 -> 344.23925 | D23: =D9*1000/(Inputs!$D$7*Inputs!$D$8*Inputs!$D$14*D22)+Inputs!$D$9 -> 357.66367 | E23: =E9*1000/(Inputs!$D$7*Inputs!$D$8*Inputs!$D$14*E22)+Inputs!$D$9 -> 462.01106 | F23: =F9*1000/(Inputs!$D$7*Inputs!$D$8*Inputs!$D$14*F22)+Inputs!$D$9 -> 597.49884
B24: Vc5 (m/s) | C24: =C10*Inputs!$D$10*(Inputs!$D$6*Inputs!$D$15*C9*1000/(Inputs!$D$7*Inputs!$D$8*Inputs!$D$14*C23))^(1/3) -> 1.7895408 | D24: =D10*Inputs!$D$10*(Inputs!$D$6*Inputs!$D$15*D9*1000/(Inputs!$D$7*Inputs!$D$8*Inputs!$D$14*D23))^(1/3) -> 1.9544743 | E24: =E10*Inputs!$D$10*(Inputs!$D$6*Inputs!$D$15*E9*1000/(Inputs!$D$7*Inputs!$D$8*Inputs!$D$14*E23))^(1/3) -> 2.7195834 | F24: =F10*Inputs!$D$10*(Inputs!$D$6*Inputs!$D$15*F9*1000/(Inputs!$D$7*Inputs!$D$8*Inputs!$D$14*F23))^(1/3) -> 3.1896687
B26: Vc (converged) [m/s] | C26: =C24 -> 1.7895408 | D26: =D24 -> 1.9544743 | E26: =E24 -> 2.7195834 | F26: =F24 -> 3.1896687 | I26: → converged after 5 successive-substitution passes
B27: Tf at fire site [°C] | C27: =C23-273.15 -> 71.089245 | D27: =D23-273.15 -> 84.513669 | E27: =E23-273.15 -> 188.86106 | F27: =F23-273.15 -> 324.34884
B28: MTFVTP measured band [m/s] | C28: 2.5 – 3.0 | D28: 2.5 – 3.0 | E28: 2.5 – 3.0 | F28: 2.5 – 3.0
B29: Design Vc (governing) [m/s] | C29: =MAX(C26,3) -> 3 | D29: =MAX(D26,3) -> 3 | E29: =MAX(E26,3) -> 3 | F29: =MAX(F26,3) -> 3.1896687 | I29: Design Vc = max(analytical Vc, 3.0 m/s floor)

Sheet FanSizing
B2: Preliminary Jet-Fan Sizing (momentum / thrust balance)
B3: Fans required to establish design Vc against tunnel resistance at the fire.
H5: Equations (full derivation on Methodology sheet):
B6: Parameter / Fire | C6: 10 MW | D6: 20 MW | E6: 50 MW | F6: 100 MW
B7: Design Vc [m/s] | C7: =CriticalVelocity!C29 -> 3 | D7: =CriticalVelocity!D29 -> 3 | E7: =CriticalVelocity!E29 -> 3 | F7: =CriticalVelocity!F29 -> 3.1896687 | H7: from CriticalVelocity sheet
B8: Air density at fire ρ_hot [kg/m³] | C8: =Inputs!$D$7*Inputs!$D$9/(CriticalVelocity!C27+273.15) -> 1.0044758 | D8: =Inputs!$D$7*Inputs!$D$9/(CriticalVelocity!D27+273.15) -> 0.96677418 | E8: =Inputs!$D$7*Inputs!$D$9/(CriticalVelocity!E27+273.15) -> 0.74842364 | F8: =Inputs!$D$7*Inputs!$D$9/(CriticalVelocity!F27+273.15) -> 0.57871242 | H8: ρ_hot = ρ₀·T₀/Tf
B9: Hydraulic diameter Dh [m] | C9: =4*Inputs!$D$14/Inputs!$D$16 -> 8.7854545 | D9: =4*Inputs!$D$14/Inputs!$D$16 -> 8.7854545 | E9: =4*Inputs!$D$14/Inputs!$D$16 -> 8.7854545 | F9: =4*Inputs!$D$14/Inputs!$D$16 -> 8.7854545 | H9: Dh = 4A/P
B10: Tunnel pressure rise required ΔP [Pa] | C10: =(Inputs!$D$19*Inputs!$D$17/C9+Inputs!$D$20)*0.5*Inputs!$D$7*C7^2 -> 82.284707 | D10: =(Inputs!$D$19*Inputs!$D$17/D9+Inputs!$D$20)*0.5*Inputs!$D$7*D7^2 -> 82.284707 | E10: =(Inputs!$D$19*Inputs!$D$17/E9+Inputs!$D$20)*0.5*Inputs!$D$7*E7^2 -> 82.284707 | F10: =(Inputs!$D$19*Inputs!$D$17/F9+Inputs!$D$20)*0.5*Inputs!$D$7*F7^2 -> 93.018166 | H10: ΔP = (f·L/Dh + ΣK)·½·ρ₀·Vc²
B11: Total thrust required [N] | C11: =C10*Inputs!$D$14 -> 4969.9963 | D11: =D10*Inputs!$D$14 -> 4969.9963 | E11: =E10*Inputs!$D$14 -> 4969.9963 | F11: =F10*Inputs!$D$14 -> 5618.2972 | H11: F_req = ΔP·A
B12: Thrust per jet fan [N] | C12: =Inputs!$D$7*Inputs!$D$24*(Inputs!$D$25-C7)*Inputs!$D$27*Inputs!$D$26 -> 1157.7946 | D12: =Inputs!$D$7*Inputs!$D$24*(Inputs!$D$25-D7)*Inputs!$D$27*Inputs!$D$26 -> 1157.7946 | E12: =Inputs!$D$7*Inputs!$D$24*(Inputs!$D$25-E7)*Inputs!$D$27*Inputs!$D$26 -> 1157.7946 | F12: =Inputs!$D$7*Inputs!$D$24*(Inputs!$D$25-F7)*Inputs!$D$27*Inputs!$D$26 -> 1150.7562 | H12: F_fan = ρ₀·Qfan·(Vjet−Vc)·k_inst·η
B13: Fans required (calc) | C13: =C11/C12 -> 4.2926409 | D13: =D11/D12 -> 4.2926409 | E13: =E11/E12 -> 4.2926409 | F13: =F11/F12 -> 4.8822655
B14: Fans required (rounded up) | C14: =ROUNDUP(C13,0) -> 5 | D14: =ROUNDUP(D13,0) -> 5 | E14: =ROUNDUP(E13,0) -> 5 | F14: =ROUNDUP(F13,0) -> 5 | H14: N = ROUNDUP(F_req / F_fan)
B16: Note: preliminary momentum balance for the establishment of critical velocity against steady tunnel resistance. Does not credit portal wind assistance or fire-throttling; SES (D3–D6) resolves the transient and confirms the operable fan count under N-1/N-2 contingencies.

Sheet Summary
B2: Summary — Preliminary Sizing Results
B3: Carried into D3 (SES build) and D8 (fan operating matrix).
B6: Design fire | C6: 10 MW (606A) | D6: 20 MW (607) | E6: 50 MW (611) | F6: 100 MW (615B)
B7: Total HRR [kW] | C7: =CriticalVelocity!C8 -> 10445 | D7: =CriticalVelocity!D8 -> 14138 | E7: =CriticalVelocity!E8 -> 49202 | F7: =CriticalVelocity!F8 -> 102659
B8: Analytical Vc [m/s] | C8: =CriticalVelocity!C26 -> 1.7895408 | D8: =CriticalVelocity!D26 -> 1.9544743 | E8: =CriticalVelocity!E26 -> 2.7195834 | F8: =CriticalVelocity!F26 -> 3.1896687
B9: Design Vc (governing) [m/s] | C9: =CriticalVelocity!C29 -> 3 | D9: =CriticalVelocity!D29 -> 3 | E9: =CriticalVelocity!E29 -> 3 | F9: =CriticalVelocity!F29 -> 3.1896687
B10: Fire-site temp Tf [°C] | C10: =CriticalVelocity!C27 -> 71.089245 | D10: =CriticalVelocity!D27 -> 84.513669 | E10: =CriticalVelocity!E27 -> 188.86106 | F10: =CriticalVelocity!F27 -> 324.34884
B11: ΔP required [Pa] | C11: =FanSizing!C10 -> 82.284707 | D11: =FanSizing!D10 -> 82.284707 | E11: =FanSizing!E10 -> 82.284707 | F11: =FanSizing!F10 -> 93.018166
B12: Total thrust required [N] | C12: =FanSizing!C11 -> 4969.9963 | D12: =FanSizing!D11 -> 4969.9963 | E12: =FanSizing!E11 -> 4969.9963 | F12: =FanSizing!F11 -> 5618.2972
B13: Jet fans required | C13: =FanSizing!C14 -> 5 | D13: =FanSizing!D14 -> 5 | E13: =FanSizing!E14 -> 5 | F13: =FanSizing!F14 -> 5
B16: Prepared by Synoptic CFD | STN-MT-CVC-002 Rev A | Basis: DBR STN-MT-DBR-001. All values recalculate from the Inputs sheet.
